Workbook

Sheet Instructions
A9: How to fill in your Business Cashbook
A11: Columns:
A13: Column A | B13: In Column A enter the date of each transaction from the bank statement
A15: Column B | B15: Code - the codes at the top of the Income & Expense columns are Account Analysis codes.
B17: Enter the code number of the column the transaction is for (e.g. Bank Fees is code 710)
A19: Column C | B19: Detail - write the particulars of the transaction, e.g. the client name for income
A21: Column D | B21: Cashbook Balance - this column calculates itself, do not type in it
A23: Column E | B23: Ref. - the cheque number or the transaction's reference
A25: Column G | B25: Bank - the amount of the transaction: income is positive, an expense is negative ( - )
A27: Column H/I | B27: GST Income/Expense - calculated from the bank amount; leave blank where there is no GST,
B29: e.g. interest, bank fees, shareholder contributions and offshore subscriptions
A31: Row 108 | B31: Bank Balance - the closing balance shown on your bank statement.
A33: Row 110 | B33: Unpresented deposits - deposits not yet on the bank statement.
A35: Row 113 | B35: Unpresented cheques - payments not yet on the bank statement.
A74: SYNTHETIC TEST DATA - NOT A REAL STATEMENT

Sheet Cashbook
A1: Company Name: TUATARA LANE CONSULTING LIMITED
A3: Cashbook for period ending 31/03/2027 | K3: * | S3: *
J4: 707 | K4: 706 | L4: 703 | M4: 704 | N4: 709 | O4: 738 | P4: 739 | Q4: 714 | R4: 710 | S4: 711 | T4: 712 | U4: 713 | V4: 715 | W4: 724 | X4: 725 | Y4: 726 | Z4: 727 | AA4: 728 | AB4: 729 | AC4: 730 | AD4: 732 | AE4: 733 | AF4: 734 | AG4: 735
A5: Date | B5: Code | C5: Detail | D5: C/Book Balance | E5: Ref | G5: Bank | H5: GST Income | I5: GST Expense | J5: Income | K5: S/Holder Contribution | N5: Purchases | O5: ACC Levy | P5: No GST Purchases (online tech. subscriptions) | Q5: Interest | R5: Bank Fees | S5: Accountancy | T5: Legal Fees | U5: Vehicle Expenses | V5: Postage & Stationery | W5: Apartment Rent | X5: Power | Y5: Entertaintment | Z5: Internet | AA5: Mobile Plan - Tui Mobile | AB5: Car Parking | AC5: Contents Insurance | AD5: Indemnity Insurance | AE5: Fakeville Council Rates/Body Corp Fees | AF5: Home Office Expenses
K6: =IF($B6=706,SUM($G6-(SUM($H6:$I6))),"") | L6: =IF($B6=703,SUM($G6-(SUM($H6:$I6))),"") | M6: =IF($B6=704,SUM($G6-(SUM($H6:$I6))),"") | N6: =IF($B6=709,SUM($G6-(SUM($H6:$I6))),"") | O6: =IF($B6=738,SUM($G6-(SUM($H6:$I6))),"") | P6: =IF($B6=739,SUM($G6-(SUM($H6:$I6))),"") | Q6: =IF($B6=714,SUM($G6-(SUM($H6:$I6))),"") | R6: =IF($B6=710,SUM($G6-(SUM($H6:$I6))),"") | S6: =IF($B6=711,SUM($G6-(SUM($H6:$I6))),"") | T6: =IF($B6=712,SUM($G6-(SUM($H6:$I6))),"") | U6: =IF($B6=713,SUM($G6-(SUM($H6:$I6))),"") | V6: =IF($B6=715,SUM($G6-(SUM($H6:$I6))),"") | W6: =IF($B6=724,SUM($G6-(SUM($H6:$I6))),"") | X6: =IF($B6=725,SUM($G6-(SUM($H6:$I6))),"") | Y6: =IF($B6=726,SUM($G6-(SUM($H6:$I6))),"") | Z6: =IF($B6=727,SUM($G6-(SUM($H6:$I6))),"") | AA6: =IF($B6=728,SUM($G6-(SUM($H6:$I6))),"") | AB6: =IF($B6=729,SUM($G6-(SUM($H6:$I6))),"") | AC6: =IF($B6=730,SUM($G6-(SUM($H6:$I6))),"") | AD6: =IF($B6=732,SUM($G6-(SUM($H6:$I6))),"") | AE6: =IF($B6=733,SUM($G6-(SUM($H6:$I6))),"") | AF6: =IF($B6=734,SUM($G6-(SUM($H6:$I6))),"") | AG6: =IF($B6=705,SUM($G6-(SUM($H6:$I6))),"") | AH6: =IF($B6=735,SUM($G6-(SUM($H6:$I6))),"") | AI6: =IF($B6=736,SUM($G6-(SUM($H6:$I6))),"") | AJ6: =IF($B6=737,SUM($G6-(SUM($H6:$I6))),"") | AK6: =IF($B6=725,SUM($G6-(SUM($H6:$I6))),"") | AL6: =IF($B6=735,SUM($G6-(SUM($H6:$I6))),"") | AM6: =IF($B6=727,SUM($G6-(SUM($H6:$I6))),"") | AN6: =IF($B6=718,SUM($G6-(SUM($H6:$I6))),"") | AO6: =IF($B6=719,SUM($G6-(SUM($H6:$I6))),"") | AP6: =IF($B6=717,SUM($G6-(SUM($H6:$I6))),"") | AQ6: =IF($B6=722,SUM($G6-(SUM($H6:$I6))),"") | AR6: =IF($B6=708,SUM($G6-(SUM($H6:$I6))),"") | AS6: =IF($B6=701,SUM($G6-(SUM($H6:$I6))),"") | AT6: =IF($B6=702,SUM($G6-(SUM($H6:$I6))),"") | AU6: =IF($B6=731,SUM($G6-(SUM($H6:$I6))),"") | AV6: =IF($B6=730,SUM($G6-(SUM($H6:$I6))),"")
B7: 707 | C7: Income - October - Client (50% progress payment received) | D7: =D6+G7 -> 0 | F7: =SUM(H7:AV7)-G7 -> 0 | G7: 0 | H7: =IF(G7/23*3>0,SUM(G7/23*3),"") | I7: =IF(G7/23*3<0,SUM(G7/23*3),"") | J7: =IF($B7=707,SUM($G7-(SUM($H7:$I7))),"") -> 0 | K7: =IF($B7=706,SUM($G7-(SUM($H7:$I7))),"") | L7: =IF($B7=703,SUM($G7-(SUM($H7:$I7))),"") | M7: =IF($B7=704,SUM($G7-(SUM($H7:$I7))),"") | N7: =IF($B7=709,SUM($G7-(SUM($H7:$I7))),"") | O7: =IF($B7=738,SUM($G7-(SUM($H7:$I7))),"") | P7: =IF($B7=739,SUM($G7-(SUM($H7:$I7))),"") | Q7: =IF($B7=714,SUM($G7-(SUM($H7:$I7))),"") | R7: =IF($B7=710,SUM($G7-(SUM($H7:$I7))),"") | S7: =IF($B7=711,SUM($G7-(SUM($H7:$I7))),"") | T7: =IF($B7=712,SUM($G7-(SUM($H7:$I7))),"") | U7: =IF($B7=713,SUM($G7-(SUM($H7:$I7))),"") | V7: =IF($B7=715,SUM($G7-(SUM($H7:$I7))),"") | W7: =IF($B7=724,SUM($G7-(SUM($H7:$I7))),"") | X7: =IF($B7=725,SUM($G7-(SUM($H7:$I7))),"") | Y7: =IF($B7=726,SUM($G7-(SUM($H7:$I7))),"") | Z7: =IF($B7=727,SUM($G7-(SUM($H7:$I7))),"") | AA7: =IF($B7=728,SUM($G7-(SUM($H7:$I7))),"") | AB7: =IF($B7=729,SUM($G7-(SUM($H7:$I7))),"") | AC7: =IF($B7=730,SUM($G7-(SUM($H7:$I7))),"") | AD7: =IF($B7=732,SUM($G7-(SUM($H7:$I7))),"") | AE7: =IF($B7=733,SUM($G7-(SUM($H7:$I7))),"") | AF7: =IF($B7=734,SUM($G7-(SUM($H7:$I7))),"") | AG7: =IF($B7=705,SUM($G7-(SUM($H7:$I7))),"") | AH7: =IF($B7=735,SUM($G7-(SUM($H7:$I7))),"") | AI7: =IF($B7=736,SUM($G7-(SUM($H7:$I7))),"") | AJ7: =IF($B7=737,SUM($G7-(SUM($H7:$I7))),"") | AK7: =IF($B7=725,SUM($G7-(SUM($H7:$I7))),"") | AL7: =IF($B7=735,SUM($G7-(SUM($H7:$I7))),"") | AM7: =IF($B7=727,SUM($G7-(SUM($H7:$I7))),"") | AN7: =IF($B7=718,SUM($G7-(SUM($H7:$I7))),"") | AO7: =IF($B7=719,SUM($G7-(SUM($H7:$I7))),"") | AP7: =IF($B7=717,SUM($G7-(SUM($H7:$I7))),"") | AQ7: =IF($B7=722,SUM($G7-(SUM($H7:$I7))),"") | AR7: =IF($B7=708,SUM($G7-(SUM($H7:$I7))),"") | AS7: =IF($B7=701,SUM($G7-(SUM($H7:$I7))),"") | AT7: =IF($B7=702,SUM($G7-(SUM($H7:$I7))),"") | AU7: =IF($B7=731,SUM($G7-(SUM($H7:$I7))),"") | AV7: =IF($B7=730,SUM($G7-(SUM($H7:$I7))),"")
B8: 725 | C8: Power - Fibrewave | D8: =D7+G8 -> 0 | F8: =SUM(H8:AV8)-G8 -> 0 | G8: 0 | H8: =IF(G8/23*3>0,SUM(G8/23*3),"") | I8: =IF(G8/23*3<0,SUM(G8/23*3),"") | J8: =IF($B8=707,SUM($G8-(SUM($H8:$I8))),"") | K8: =IF($B8=706,SUM($G8-(SUM($H8:$I8))),"") | L8: =IF($B8=703,SUM($G8-(SUM($H8:$I8))),"") | M8: =IF($B8=704,SUM($G8-(SUM($H8:$I8))),"") | N8: =IF($B8=709,SUM($G8-(SUM($H8:$I8))),"") | O8: =IF($B8=738,SUM($G8-(SUM($H8:$I8))),"") | P8: =IF($B8=739,SUM($G8-(SUM($H8:$I8))),"") | Q8: =IF($B8=714,SUM($G8-(SUM($H8:$I8))),"") | R8: =IF($B8=710,SUM($G8-(SUM($H8:$I8))),"") | S8: =IF($B8=711,SUM($G8-(SUM($H8:$I8))),"") | T8: =IF($B8=712,SUM($G8-(SUM($H8:$I8))),"") | U8: =IF($B8=713,SUM($G8-(SUM($H8:$I8))),"") | V8: =IF($B8=715,SUM($G8-(SUM($H8:$I8))),"") | W8: =IF($B8=724,SUM($G8-(SUM($H8:$I8))),"") | X8: =IF($B8=725,SUM($G8-(SUM($H8:$I8))),"") -> 0 | Y8: =IF($B8=726,SUM($G8-(SUM($H8:$I8))),"") | Z8: =IF($B8=727,SUM($G8-(SUM($H8:$I8))),"") | AA8: =IF($B8=728,SUM($G8-(SUM($H8:$I8))),"") | AB8: =IF($B8=729,SUM($G8-(SUM($H8:$I8))),"") | AC8: =IF($B8=730,SUM($G8-(SUM($H8:$I8))),"") | AD8: =IF($B8=732,SUM($G8-(SUM($H8:$I8))),"") | AE8: =IF($B8=733,SUM($G8-(SUM($H8:$I8))),"") | AF8: =IF($B8=734,SUM($G8-(SUM($H8:$I8))),"") | AG8: =IF($B8=705,SUM($G8-(SUM($H8:$I8))),"") | AH8: =IF($B8=735,SUM($G8-(SUM($H8:$I8))),"") | AI8: =IF($B8=736,SUM($G8-(SUM($H8:$I8))),"") | AJ8: =IF($B8=737,SUM($G8-(SUM($H8:$I8))),"") | AK8: =IF($B8=725,SUM($G8-(SUM($H8:$I8))),"") -> 0 | AL8: =IF($B8=735,SUM($G8-(SUM($H8:$I8))),"") | AM8: =IF($B8=727,SUM($G8-(SUM($H8:$I8))),"") | AN8: =IF($B8=718,SUM($G8-(SUM($H8:$I8))),"") | AO8: =IF($B8=719,SUM($G8-(SUM($H8:$I8))),"") | AP8: =IF($B8=717,SUM($G8-(SUM($H8:$I8))),"") | AQ8: =IF($B8=722,SUM($G8-(SUM($H8:$I8))),"") | AR8: =IF($B8=708,SUM($G8-(SUM($H8:$I8))),"") | AS8: =IF($B8=701,SUM($G8-(SUM($H8:$I8))),"") | AT8: =IF($B8=702,SUM($G8-(SUM($H8:$I8))),"") | AU8: =IF($B8=731,SUM($G8-(SUM($H8:$I8))),"") | AV8: =IF($B8=730,SUM($G8-(SUM($H8:$I8))),"")
B9: 726 | C9: Entertainment (Business Lunch/Coffee/Meals/Drinks) | D9: =D8+G9 -> 0 | F9: =SUM(H9:AV9)-G9 -> 0 | G9: =-(OtherCalculation!C5) -> 0 | H9: =IF(G9/23*3>0,SUM(G9/23*3),"") | I9: =IF(G9/23*3<0,SUM(G9/23*3),"") | J9: =IF($B9=707,SUM($G9-(SUM($H9:$I9))),"") | K9: =IF($B9=706,SUM($G9-(SUM($H9:$I9))),"") | L9: =IF($B9=703,SUM($G9-(SUM($H9:$I9))),"") | M9: =IF($B9=704,SUM($G9-(SUM($H9:$I9))),"") | N9: =IF($B9=709,SUM($G9-(SUM($H9:$I9))),"") | O9: =IF($B9=738,SUM($G9-(SUM($H9:$I9))),"") | P9: =IF($B9=739,SUM($G9-(SUM($H9:$I9))),"") | Q9: =IF($B9=714,SUM($G9-(SUM($H9:$I9))),"") | R9: =IF($B9=710,SUM($G9-(SUM($H9:$I9))),"") | S9: =IF($B9=711,SUM($G9-(SUM($H9:$I9))),"") | T9: =IF($B9=712,SUM($G9-(SUM($H9:$I9))),"") | U9: =IF($B9=713,SUM($G9-(SUM($H9:$I9))),"") | V9: =IF($B9=715,SUM($G9-(SUM($H9:$I9))),"") | W9: =IF($B9=724,SUM($G9-(SUM($H9:$I9))),"") | X9: =IF($B9=725,SUM($G9-(SUM($H9:$I9))),"") | Y9: =IF($B9=726,SUM($G9-(SUM($H9:$I9))),"") -> 0 | Z9: =IF($B9=727,SUM($G9-(SUM($H9:$I9))),"") | AA9: =IF($B9=728,SUM($G9-(SUM($H9:$I9))),"") | AB9: =IF($B9=729,SUM($G9-(SUM($H9:$I9))),"") | AC9: =IF($B9=730,SUM($G9-(SUM($H9:$I9))),"") | AD9: =IF($B9=732,SUM($G9-(SUM($H9:$I9))),"") | AE9: =IF($B9=733,SUM($G9-(SUM($H9:$I9))),"") | AF9: =IF($B9=734,SUM($G9-(SUM($H9:$I9))),"") | AG9: =IF($B9=705,SUM($G9-(SUM($H9:$I9))),"") | AH9: =IF($B9=735,SUM($G9-(SUM($H9:$I9))),"") | AI9: =IF($B9=736,SUM($G9-(SUM($H9:$I9))),"") | AJ9: =IF($B9=737,SUM($G9-(SUM($H9:$I9))),"") | AK9: =IF($B9=725,SUM($G9-(SUM($H9:$I9))),"") | AL9: =IF($B9=735,SUM($G9-(SUM($H9:$I9))),"") | AM9: =IF($B9=727,SUM($G9-(SUM($H9:$I9))),"") | AN9: =IF($B9=718,SUM($G9-(SUM($H9:$I9))),"") | AO9: =IF($B9=719,SUM($G9-(SUM($H9:$I9))),"") | AP9: =IF($B9=717,SUM($G9-(SUM($H9:$I9))),"") | AQ9: =IF($B9=722,SUM($G9-(SUM($H9:$I9))),"") | AR9: =IF($B9=708,SUM($G9-(SUM($H9:$I9))),"") | AS9: =IF($B9=701,SUM($G9-(SUM($H9:$I9))),"") | AT9: =IF($B9=702,SUM($G9-(SUM($H9:$I9))),"") | AU9: =IF($B9=731,SUM($G9-(SUM($H9:$I9))),"") | AV9: =IF($B9=730,SUM($G9-(SUM($H9:$I9))),"")
B10: 727 | C10: Internet - Fibrewave | D10: =D9+G10 -> 0 | F10: =SUM(H10:AV10)-G10 -> 0 | G10: 0 | H10: =IF(G10/23*3>0,SUM(G10/23*3),"") | I10: =IF(G10/23*3<0,SUM(G10/23*3),"") | J10: =IF($B10=707,SUM($G10-(SUM($H10:$I10))),"") | K10: =IF($B10=706,SUM($G10-(SUM($H10:$I10))),"") | L10: =IF($B10=703,SUM($G10-(SUM($H10:$I10))),"") | M10: =IF($B10=704,SUM($G10-(SUM($H10:$I10))),"") | N10: =IF($B10=709,SUM($G10-(SUM($H10:$I10))),"") | O10: =IF($B10=738,SUM($G10-(SUM($H10:$I10))),"") | P10: =IF($B10=739,SUM($G10-(SUM($H10:$I10))),"") | Q10: =IF($B10=714,SUM($G10-(SUM($H10:$I10))),"") | R10: =IF($B10=710,SUM($G10-(SUM($H10:$I10))),"") | S10: =IF($B10=711,SUM($G10-(SUM($H10:$I10))),"") | T10: =IF($B10=712,SUM($G10-(SUM($H10:$I10))),"") | U10: =IF($B10=713,SUM($G10-(SUM($H10:$I10))),"") | V10: =IF($B10=715,SUM($G10-(SUM($H10:$I10))),"") | W10: =IF($B10=724,SUM($G10-(SUM($H10:$I10))),"") | X10: =IF($B10=725,SUM($G10-(SUM($H10:$I10))),"") | Y10: =IF($B10=726,SUM($G10-(SUM($H10:$I10))),"") | Z10: =IF($B10=727,SUM($G10-(SUM($H10:$I10))),"") -> 0 | AA10: =IF($B10=728,SUM($G10-(SUM($H10:$I10))),"") | AB10: =IF($B10=729,SUM($G10-(SUM($H10:$I10))),"") | AC10: =IF($B10=730,SUM($G10-(SUM($H10:$I10))),"") | AD10: =IF($B10=732,SUM($G10-(SUM($H10:$I10))),"") | AE10: =IF($B10=733,SUM($G10-(SUM($H10:$I10))),"") | AF10: =IF($B10=734,SUM($G10-(SUM($H10:$I10))),"") | AG10: =IF($B10=705,SUM($G10-(SUM($H10:$I10))),"") | AH10: =IF($B10=735,SUM($G10-(SUM($H10:$I10))),"") | AI10: =IF($B10=736,SUM($G10-(SUM($H10:$I10))),"") | AJ10: =IF($B10=737,SUM($G10-(SUM($H10:$I10))),"") | AK10: =IF($B10=725,SUM($G10-(SUM($H10:$I10))),"") | AL10: =IF($B10=735,SUM($G10-(SUM($H10:$I10))),"") | AM10: =IF($B10=727,SUM($G10-(SUM($H10:$I10))),"") -> 0 | AN10: =IF($B10=718,SUM($G10-(SUM($H10:$I10))),"") | AO10: =IF($B10=719,SUM($G10-(SUM($H10:$I10))),"") | AP10: =IF($B10=717,SUM($G10-(SUM($H10:$I10))),"") | AQ10: =IF($B10=722,SUM($G10-(SUM($H10:$I10))),"") | AR10: =IF($B10=708,SUM($G10-(SUM($H10:$I10))),"") | AS10: =IF($B10=701,SUM($G10-(SUM($H10:$I10))),"") | AT10: =IF($B10=702,SUM($G10-(SUM($H10:$I10))),"") | AU10: =IF($B10=731,SUM($G10-(SUM($H10:$I10))),"") | AV10: =IF($B10=730,SUM($G10-(SUM($H10:$I10))),"")
B11: 728 | C11: Mobile Plan - Tui Mobile NZ | D11: =D10+G11 -> 0 | F11: =SUM(H11:AV11)-G11 -> 0 | G11: 0 | H11: =IF(G11/23*3>0,SUM(G11/23*3),"") | I11: =IF(G11/23*3<0,SUM(G11/23*3),"") | J11: =IF($B11=707,SUM($G11-(SUM($H11:$I11))),"") | K11: =IF($B11=706,SUM($G11-(SUM($H11:$I11))),"") | L11: =IF($B11=703,SUM($G11-(SUM($H11:$I11))),"") | M11: =IF($B11=704,SUM($G11-(SUM($H11:$I11))),"") | N11: =IF($B11=709,SUM($G11-(SUM($H11:$I11))),"") | O11: =IF($B11=738,SUM($G11-(SUM($H11:$I11))),"") | P11: =IF($B11=739,SUM($G11-(SUM($H11:$I11))),"") | Q11: =IF($B11=714,SUM($G11-(SUM($H11:$I11))),"") | R11: =IF($B11=710,SUM($G11-(SUM($H11:$I11))),"") | S11: =IF($B11=711,SUM($G11-(SUM($H11:$I11))),"") | T11: =IF($B11=712,SUM($G11-(SUM($H11:$I11))),"") | U11: =IF($B11=713,SUM($G11-(SUM($H11:$I11))),"") | V11: =IF($B11=715,SUM($G11-(SUM($H11:$I11))),"") | W11: =IF($B11=724,SUM($G11-(SUM($H11:$I11))),"") | X11: =IF($B11=725,SUM($G11-(SUM($H11:$I11))),"") | Y11: =IF($B11=726,SUM($G11-(SUM($H11:$I11))),"") | Z11: =IF($B11=727,SUM($G11-(SUM($H11:$I11))),"") | AA11: =IF($B11=728,SUM($G11-(SUM($H11:$I11))),"") -> 0 | AB11: =IF($B11=729,SUM($G11-(SUM($H11:$I11))),"") | AC11: =IF($B11=730,SUM($G11-(SUM($H11:$I11))),"") | AD11: =IF($B11=732,SUM($G11-(SUM($H11:$I11))),"") | AE11: =IF($B11=733,SUM($G11-(SUM($H11:$I11))),"") | AF11: =IF($B11=734,SUM($G11-(SUM($H11:$I11))),"") | AG11: =IF($B11=705,SUM($G11-(SUM($H11:$I11))),"") | AH11: =IF($B11=735,SUM($G11-(SUM($H11:$I11))),"") | AI11: =IF($B11=736,SUM($G11-(SUM($H11:$I11))),"") | AJ11: =IF($B11=737,SUM($G11-(SUM($H11:$I11))),"") | AK11: =IF($B11=725,SUM($G11-(SUM($H11:$I11))),"") | AL11: =IF($B11=735,SUM($G11-(SUM($H11:$I11))),"") | AM11: =IF($B11=727,SUM($G11-(SUM($H11:$I11))),"") | AN11: =IF($B11=718,SUM($G11-(SUM($H11:$I11))),"") | AO11: =IF($B11=719,SUM($G11-(SUM($H11:$I11))),"") | AP11: =IF($B11=717,SUM($G11-(SUM($H11:$I11))),"") | AQ11: =IF($B11=722,SUM($G11-(SUM($H11:$I11))),"") | AR11: =IF($B11=708,SUM($G11-(SUM($H11:$I11))),"") | AS11: =IF($B11=701,SUM($G11-(SUM($H11:$I11))),"") | AT11: =IF($B11=702,SUM($G11-(SUM($H11:$I11))),"") | AU11: =IF($B11=731,SUM($G11-(SUM($H11:$I11))),"") | AV11: =IF($B11=730,SUM($G11-(SUM($H11:$I11))),"")
B12: 729 | C12: Car Park Fees | D12: =D11+G12 -> 0 | F12: =SUM(H12:AV12)-G12 -> 0 | G12: 0 | H12: =IF(G12/23*3>0,SUM(G12/23*3),"") | I12: =IF(G12/23*3<0,SUM(G12/23*3),"") | J12: =IF($B12=707,SUM($G12-(SUM($H12:$I12))),"") | K12: =IF($B12=706,SUM($G12-(SUM($H12:$I12))),"") | L12: =IF($B12=703,SUM($G12-(SUM($H12:$I12))),"") | M12: =IF($B12=704,SUM($G12-(SUM($H12:$I12))),"") | N12: =IF($B12=709,SUM($G12-(SUM($H12:$I12))),"") | O12: =IF($B12=738,SUM($G12-(SUM($H12:$I12))),"") | P12: =IF($B12=739,SUM($G12-(SUM($H12:$I12))),"") | Q12: =IF($B12=714,SUM($G12-(SUM($H12:$I12))),"") | R12: =IF($B12=710,SUM($G12-(SUM($H12:$I12))),"") | S12: =IF($B12=711,SUM($G12-(SUM($H12:$I12))),"") | T12: =IF($B12=712,SUM($G12-(SUM($H12:$I12))),"") | U12: =IF($B12=713,SUM($G12-(SUM($H12:$I12))),"") | V12: =IF($B12=715,SUM($G12-(SUM($H12:$I12))),"") | W12: =IF($B12=724,SUM($G12-(SUM($H12:$I12))),"") | X12: =IF($B12=725,SUM($G12-(SUM($H12:$I12))),"") | Y12: =IF($B12=726,SUM($G12-(SUM($H12:$I12))),"") | Z12: =IF($B12=727,SUM($G12-(SUM($H12:$I12))),"") | AA12: =IF($B12=728,SUM($G12-(SUM($H12:$I12))),"") | AB12: =IF($B12=729,SUM($G12-(SUM($H12:$I12))),"") -> 0 | AC12: =IF($B12=730,SUM($G12-(SUM($H12:$I12))),"") | AD12: =IF($B12=732,SUM($G12-(SUM($H12:$I12))),"") | AE12: =IF($B12=733,SUM($G12-(SUM($H12:$I12))),"") | AF12: =IF($B12=734,SUM($G12-(SUM($H12:$I12))),"") | AG12: =IF($B12=705,SUM($G12-(SUM($H12:$I12))),"") | AH12: =IF($B12=735,SUM($G12-(SUM($H12:$I12))),"") | AI12: =IF($B12=736,SUM($G12-(SUM($H12:$I12))),"") | AJ12: =IF($B12=737,SUM($G12-(SUM($H12:$I12))),"") | AK12: =IF($B12=725,SUM($G12-(SUM($H12:$I12))),"") | AL12: =IF($B12=735,SUM($G12-(SUM($H12:$I12))),"") | AM12: =IF($B12=727,SUM($G12-(SUM($H12:$I12))),"") | AN12: =IF($B12=718,SUM($G12-(SUM($H12:$I12))),"") | AO12: =IF($B12=719,SUM($G12-(SUM($H12:$I12))),"") | AP12: =IF($B12=717,SUM($G12-(SUM($H12:$I12))),"") | AQ12: =IF($B12=722,SUM($G12-(SUM($H12:$I12))),"") | AR12: =IF($B12=708,SUM($G12-(SUM($H12:$I12))),"") | AS12: =IF($B12=701,SUM($G12-(SUM($H12:$I12))),"") | AT12: =IF($B12=702,SUM($G12-(SUM($H12:$I12))),"") | AU12: =IF($B12=731,SUM($G12-(SUM($H12:$I12))),"") | AV12: =IF($B12=730,SUM($G12-(SUM($H12:$I12))),"")
B13: 734 | C13: Home Office Expenses | D13: =D12+G13 -> 0 | F13: =SUM(H13:AV13)-G13 -> 0 | G13: 0 | H13: =IF(G13/23*3>0,SUM(G13/23*3),"") | I13: =IF(G13/23*3<0,SUM(G13/23*3),"") | J13: =IF($B13=707,SUM($G13-(SUM($H13:$I13))),"") | K13: =IF($B13=706,SUM($G13-(SUM($H13:$I13))),"") | L13: =IF($B13=703,SUM($G13-(SUM($H13:$I13))),"") | M13: =IF($B13=704,SUM($G13-(SUM($H13:$I13))),"") | N13: =IF($B13=709,SUM($G13-(SUM($H13:$I13))),"") | O13: =IF($B13=738,SUM($G13-(SUM($H13:$I13))),"") | P13: =IF($B13=739,SUM($G13-(SUM($H13:$I13))),"") | Q13: =IF($B13=714,SUM($G13-(SUM($H13:$I13))),"") | R13: =IF($B13=710,SUM($G13-(SUM($H13:$I13))),"") | S13: =IF($B13=711,SUM($G13-(SUM($H13:$I13))),"") | T13: =IF($B13=712,SUM($G13-(SUM($H13:$I13))),"") | U13: =IF($B13=713,SUM($G13-(SUM($H13:$I13))),"") | V13: =IF($B13=715,SUM($G13-(SUM($H13:$I13))),"") | W13: =IF($B13=724,SUM($G13-(SUM($H13:$I13))),"") | X13: =IF($B13=725,SUM($G13-(SUM($H13:$I13))),"") | Y13: =IF($B13=726,SUM($G13-(SUM($H13:$I13))),"") | Z13: =IF($B13=727,SUM($G13-(SUM($H13:$I13))),"") | AA13: =IF($B13=728,SUM($G13-(SUM($H13:$I13))),"") | AB13: =IF($B13=729,SUM($G13-(SUM($H13:$I13))),"") | AC13: =IF($B13=730,SUM($G13-(SUM($H13:$I13))),"") | AD13: =IF($B13=732,SUM($G13-(SUM($H13:$I13))),"") | AE13: =IF($B13=733,SUM($G13-(SUM($H13:$I13))),"") | AF13: =IF($B13=734,SUM($G13-(SUM($H13:$I13))),"") -> 0 | AG13: =IF($B13=705,SUM($G13-(SUM($H13:$I13))),"") | AH13: =IF($B13=735,SUM($G13-(SUM($H13:$I13))),"") | AI13: =IF($B13=736,SUM($G13-(SUM($H13:$I13))),"") | AJ13: =IF($B13=737,SUM($G13-(SUM($H13:$I13))),"") | AK13: =IF($B13=725,SUM($G13-(SUM($H13:$I13))),"") | AL13: =IF($B13=735,SUM($G13-(SUM($H13:$I13))),"") | AM13: =IF($B13=727,SUM($G13-(SUM($H13:$I13))),"") | AN13: =IF($B13=718,SUM($G13-(SUM($H13:$I13))),"") | AO13: =IF($B13=719,SUM($G13-(SUM($H13:$I13))),"") | AP13: =IF($B13=717,SUM($G13-(SUM($H13:$I13))),"") | AQ13: =IF($B13=722,SUM($G13-(SUM($H13:$I13))),"") | AR13: =IF($B13=708,SUM($G13-(SUM($H13:$I13))),"") | AS13: =IF($B13=701,SUM($G13-(SUM($H13:$I13))),"") | AT13: =IF($B13=702,SUM($G13-(SUM($H13:$I13))),"") | AU13: =IF($B13=731,SUM($G13-(SUM($H13:$I13))),"") | AV13: =IF($B13=730,SUM($G13-(SUM($H13:$I13))),"")
B14: 734 | C14: Home Office Expenses | D14: =D13+G14 -> 0 | F14: =SUM(H14:AV14)-G14 -> 0 | G14: 0 | H14: =IF(G14/23*3>0,SUM(G14/23*3),"") | I14: =IF(G14/23*3<0,SUM(G14/23*3),"") | J14: =IF($B14=707,SUM($G14-(SUM($H14:$I14))),"") | K14: =IF($B14=706,SUM($G14-(SUM($H14:$I14))),"") | L14: =IF($B14=703,SUM($G14-(SUM($H14:$I14))),"") | M14: =IF($B14=704,SUM($G14-(SUM($H14:$I14))),"") | N14: =IF($B14=709,SUM($G14-(SUM($H14:$I14))),"") | O14: =IF($B14=738,SUM($G14-(SUM($H14:$I14))),"") | P14: =IF($B14=739,SUM($G14-(SUM($H14:$I14))),"") | Q14: =IF($B14=714,SUM($G14-(SUM($H14:$I14))),"") | R14: =IF($B14=710,SUM($G14-(SUM($H14:$I14))),"") | S14: =IF($B14=711,SUM($G14-(SUM($H14:$I14))),"") | T14: =IF($B14=712,SUM($G14-(SUM($H14:$I14))),"") | U14: =IF($B14=713,SUM($G14-(SUM($H14:$I14))),"") | V14: =IF($B14=715,SUM($G14-(SUM($H14:$I14))),"") | W14: =IF($B14=724,SUM($G14-(SUM($H14:$I14))),"") | X14: =IF($B14=725,SUM($G14-(SUM($H14:$I14))),"") | Y14: =IF($B14=726,SUM($G14-(SUM($H14:$I14))),"") | Z14: =IF($B14=727,SUM($G14-(SUM($H14:$I14))),"") | AA14: =IF($B14=728,SUM($G14-(SUM($H14:$I14))),"") | AB14: =IF($B14=729,SUM($G14-(SUM($H14:$I14))),"") | AC14: =IF($B14=730,SUM($G14-(SUM($H14:$I14))),"") | AD14: =IF($B14=732,SUM($G14-(SUM($H14:$I14))),"") | AE14: =IF($B14=733,SUM($G14-(SUM($H14:$I14))),"") | AF14: =IF($B14=734,SUM($G14-(SUM($H14:$I14))),"") -> 0 | AG14: =IF($B14=705,SUM($G14-(SUM($H14:$I14))),"") | AH14: =IF($B14=735,SUM($G14-(SUM($H14:$I14))),"") | AI14: =IF($B14=736,SUM($G14-(SUM($H14:$I14))),"") | AJ14: =IF($B14=737,SUM($G14-(SUM($H14:$I14))),"") | AK14: =IF($B14=725,SUM($G14-(SUM($H14:$I14))),"") | AL14: =IF($B14=735,SUM($G14-(SUM($H14:$I14))),"") | AM14: =IF($B14=727,SUM($G14-(SUM($H14:$I14))),"") | AN14: =IF($B14=718,SUM($G14-(SUM($H14:$I14))),"") | AO14: =IF($B14=719,SUM($G14-(SUM($H14:$I14))),"") | AP14: =IF($B14=717,SUM($G14-(SUM($H14:$I14))),"") | AQ14: =IF($B14=722,SUM($G14-(SUM($H14:$I14))),"") | AR14: =IF($B14=708,SUM($G14-(SUM($H14:$I14))),"") | AS14: =IF($B14=701,SUM($G14-(SUM($H14:$I14))),"") | AT14: =IF($B14=702,SUM($G14-(SUM($H14:$I14))),"") | AU14: =IF($B14=731,SUM($G14-(SUM($H14:$I14))),"") | AV14: =IF($B14=730,SUM($G14-(SUM($H14:$I14))),"")
B15: 734 | C15: Home Office Expenses | D15: =D14+G15 -> 0 | F15: =SUM(H15:AV15)-G15 -> 0 | G15: 0 | H15: =IF(G15/23*3>0,SUM(G15/23*3),"") | I15: =IF(G15/23*3<0,SUM(G15/23*3),"") | J15: =IF($B15=707,SUM($G15-(SUM($H15:$I15))),"") | K15: =IF($B15=706,SUM($G15-(SUM($H15:$I15))),"") | L15: =IF($B15=703,SUM($G15-(SUM($H15:$I15))),"") | M15: =IF($B15=704,SUM($G15-(SUM($H15:$I15))),"") | N15: =IF($B15=709,SUM($G15-(SUM($H15:$I15))),"") | O15: =IF($B15=738,SUM($G15-(SUM($H15:$I15))),"") | P15: =IF($B15=739,SUM($G15-(SUM($H15:$I15))),"") | Q15: =IF($B15=714,SUM($G15-(SUM($H15:$I15))),"") | R15: =IF($B15=710,SUM($G15-(SUM($H15:$I15))),"") | S15: =IF($B15=711,SUM($G15-(SUM($H15:$I15))),"") | T15: =IF($B15=712,SUM($G15-(SUM($H15:$I15))),"") | U15: =IF($B15=713,SUM($G15-(SUM($H15:$I15))),"") | V15: =IF($B15=715,SUM($G15-(SUM($H15:$I15))),"") | W15: =IF($B15=724,SUM($G15-(SUM($H15:$I15))),"") | X15: =IF($B15=725,SUM($G15-(SUM($H15:$I15))),"") | Y15: =IF($B15=726,SUM($G15-(SUM($H15:$I15))),"") | Z15: =IF($B15=727,SUM($G15-(SUM($H15:$I15))),"") | AA15: =IF($B15=728,SUM($G15-(SUM($H15:$I15))),"") | AB15: =IF($B15=729,SUM($G15-(SUM($H15:$I15))),"") | AC15: =IF($B15=730,SUM($G15-(SUM($H15:$I15))),"") | AD15: =IF($B15=732,SUM($G15-(SUM($H15:$I15))),"") | AE15: =IF($B15=733,SUM($G15-(SUM($H15:$I15))),"") | AF15: =IF($B15=734,SUM($G15-(SUM($H15:$I15))),"") -> 0 | AG15: =IF($B15=705,SUM($G15-(SUM($H15:$I15))),"") | AH15: =IF($B15=735,SUM($G15-(SUM($H15:$I15))),"") | AI15: =IF($B15=736,SUM($G15-(SUM($H15:$I15))),"") | AJ15: =IF($B15=737,SUM($G15-(SUM($H15:$I15))),"") | AK15: =IF($B15=725,SUM($G15-(SUM($H15:$I15))),"") | AL15: =IF($B15=735,SUM($G15-(SUM($H15:$I15))),"") | AM15: =IF($B15=727,SUM($G15-(SUM($H15:$I15))),"") | AN15: =IF($B15=718,SUM($G15-(SUM($H15:$I15))),"") | AO15: =IF($B15=719,SUM($G15-(SUM($H15:$I15))),"") | AP15: =IF($B15=717,SUM($G15-(SUM($H15:$I15))),"") | AQ15: =IF($B15=722,SUM($G15-(SUM($H15:$I15))),"") | AR15: =IF($B15=708,SUM($G15-(SUM($H15:$I15))),"") | AS15: =IF($B15=701,SUM($G15-(SUM($H15:$I15))),"") | AT15: =IF($B15=702,SUM($G15-(SUM($H15:$I15))),"") | AU15: =IF($B15=731,SUM($G15-(SUM($H15:$I15))),"") | AV15: =IF($B15=730,SUM($G15-(SUM($H15:$I15))),"")
B16: 724 | C16: Apartment Rent | D16: =D15+G16 -> 0 | F16: =SUM(H16:AV16)-G16 -> 0 | G16: 0 | H16: =IF(G16/23*3>0,SUM(G16/23*3),"") | J16: =IF($B16=707,SUM($G16-(SUM($H16:$I16))),"") | K16: =IF($B16=706,SUM($G16-(SUM($H16:$I16))),"") | L16: =IF($B16=703,SUM($G16-(SUM($H16:$I16))),"") | M16: =IF($B16=704,SUM($G16-(SUM($H16:$I16))),"") | N16: =IF($B16=709,SUM($G16-(SUM($H16:$I16))),"") | O16: =IF($B16=738,SUM($G16-(SUM($H16:$I16))),"") | P16: =IF($B16=739,SUM($G16-(SUM($H16:$I16))),"") | Q16: =IF($B16=714,SUM($G16-(SUM($H16:$I16))),"") | R16: =IF($B16=710,SUM($G16-(SUM($H16:$I16))),"") | S16: =IF($B16=711,SUM($G16-(SUM($H16:$I16))),"") | T16: =IF($B16=712,SUM($G16-(SUM($H16:$I16))),"") | U16: =IF($B16=713,SUM($G16-(SUM($H16:$I16))),"") | V16: =IF($B16=715,SUM($G16-(SUM($H16:$I16))),"") | W16: =IF($B16=724,SUM($G16-(SUM($H16:$I16))),"") -> 0 | X16: =IF($B16=725,SUM($G16-(SUM($H16:$I16))),"") | Y16: =IF($B16=726,SUM($G16-(SUM($H16:$I16))),"") | Z16: =IF($B16=727,SUM($G16-(SUM($H16:$I16))),"") | AA16: =IF($B16=728,SUM($G16-(SUM($H16:$I16))),"") | AB16: =IF($B16=729,SUM($G16-(SUM($H16:$I16))),"") | AC16: =IF($B16=730,SUM($G16-(SUM($H16:$I16))),"") | AD16: =IF($B16=732,SUM($G16-(SUM($H16:$I16))),"") | AE16: =IF($B16=733,SUM($G16-(SUM($H16:$I16))),"") | AF16: =IF($B16=734,SUM($G16-(SUM($H16:$I16))),"") | AG16: =IF($B16=705,SUM($G16-(SUM($H16:$I16))),"") | AH16: =IF($B16=735,SUM($G16-(SUM($H16:$I16))),"") | AI16: =IF($B16=736,SUM($G16-(SUM($H16:$I16))),"") | AJ16: =IF($B16=737,SUM($G16-(SUM($H16:$I16))),"") | AK16: =IF($B16=725,SUM($G16-(SUM($H16:$I16))),"") | AL16: =IF($B16=735,SUM($G16-(SUM($H16:$I16))),"") | AM16: =IF($B16=727,SUM($G16-(SUM($H16:$I16))),"") | AN16: =IF($B16=718,SUM($G16-(SUM($H16:$I16))),"") | AO16: =IF($B16=719,SUM($G16-(SUM($H16:$I16))),"") | AP16: =IF($B16=717,SUM($G16-(SUM($H16:$I16))),"") | AQ16: =IF($B16=722,SUM($G16-(SUM($H16:$I16))),"") | AR16: =IF($B16=708,SUM($G16-(SUM($H16:$I16))),"") | AS16: =IF($B16=701,SUM($G16-(SUM($H16:$I16))),"") | AT16: =IF($B16=702,SUM($G16-(SUM($H16:$I16))),"") | AU16: =IF($B16=731,SUM($G16-(SUM($H16:$I16))),"") | AV16: =IF($B16=730,SUM($G16-(SUM($H16:$I16))),"")
B17: 710 | C17: Bank Fees | D17: =D16+G17 -> 0 | F17: =SUM(H17:AV17)-G17 -> 0 | G17: 0 | H17: =IF(G17/23*3>0,SUM(G17/23*3),"") | J17: =IF($B17=707,SUM($G17-(SUM($H17:$I17))),"") | K17: =IF($B17=706,SUM($G17-(SUM($H17:$I17))),"") | L17: =IF($B17=703,SUM($G17-(SUM($H17:$I17))),"") | M17: =IF($B17=704,SUM($G17-(SUM($H17:$I17))),"") | N17: =IF($B17=709,SUM($G17-(SUM($H17:$I17))),"") | O17: =IF($B17=738,SUM($G17-(SUM($H17:$I17))),"") | P17: =IF($B17=739,SUM($G17-(SUM($H17:$I17))),"") | Q17: =IF($B17=714,SUM($G17-(SUM($H17:$I17))),"") | R17: =IF($B17=710,SUM($G17-(SUM($H17:$I17))),"") -> 0 | S17: =IF($B17=711,SUM($G17-(SUM($H17:$I17))),"") | T17: =IF($B17=712,SUM($G17-(SUM($H17:$I17))),"") | U17: =IF($B17=713,SUM($G17-(SUM($H17:$I17))),"") | V17: =IF($B17=715,SUM($G17-(SUM($H17:$I17))),"") | W17: =IF($B17=724,SUM($G17-(SUM($H17:$I17))),"") | X17: =IF($B17=725,SUM($G17-(SUM($H17:$I17))),"") | Y17: =IF($B17=726,SUM($G17-(SUM($H17:$I17))),"") | Z17: =IF($B17=727,SUM($G17-(SUM($H17:$I17))),"") | AA17: =IF($B17=728,SUM($G17-(SUM($H17:$I17))),"") | AB17: =IF($B17=729,SUM($G17-(SUM($H17:$I17))),"") | AC17: =IF($B17=730,SUM($G17-(SUM($H17:$I17))),"") | AD17: =IF($B17=732,SUM($G17-(SUM($H17:$I17))),"") | AE17: =IF($B17=733,SUM($G17-(SUM($H17:$I17))),"") | AF17: =IF($B17=734,SUM($G17-(SUM($H17:$I17))),"") | AG17: =IF($B17=705,SUM($G17-(SUM($H17:$I17))),"") | AH17: =IF($B17=735,SUM($G17-(SUM($H17:$I17))),"") | AI17: =IF($B17=736,SUM($G17-(SUM($H17:$I17))),"") | AJ17: =IF($B17=737,SUM($G17-(SUM($H17:$I17))),"") | AK17: =IF($B17=725,SUM($G17-(SUM($H17:$I17))),"") | AL17: =IF($B17=735,SUM($G17-(SUM($H17:$I17))),"") | AM17: =IF($B17=727,SUM($G17-(SUM($H17:$I17))),"") | AN17: =IF($B17=718,SUM($G17-(SUM($H17:$I17))),"") | AO17: =IF($B17=719,SUM($G17-(SUM($H17:$I17))),"") | AP17: =IF($B17=717,SUM($G17-(SUM($H17:$I17))),"") | AQ17: =IF($B17=722,SUM($G17-(SUM($H17:$I17))),"") | AR17: =IF($B17=708,SUM($G17-(SUM($H17:$I17))),"") | AS17: =IF($B17=701,SUM($G17-(SUM($H17:$I17))),"") | AT17: =IF($B17=702,SUM($G17-(SUM($H17:$I17))),"") | AU17: =IF($B17=731,SUM($G17-(SUM($H17:$I17))),"") | AV17: =IF($B17=730,SUM($G17-(SUM($H17:$I17))),"")
B18: 711 | C18: Accountant Fee (Accountancy) | D18: =D17+G18 -> 0 | F18: =SUM(H18:AV18)-G18 -> 0 | G18: 0 | H18: =IF(G18/23*3>0,SUM(G18/23*3),"") | I18: =IF(G18/23*3<0,SUM(G18/23*3),"") | J18: =IF($B18=707,SUM($G18-(SUM($H18:$I18))),"") | K18: =IF($B18=706,SUM($G18-(SUM($H18:$I18))),"") | L18: =IF($B18=703,SUM($G18-(SUM($H18:$I18))),"") | M18: =IF($B18=704,SUM($G18-(SUM($H18:$I18))),"") | N18: =IF($B18=709,SUM($G18-(SUM($H18:$I18))),"") | O18: =IF($B18=738,SUM($G18-(SUM($H18:$I18))),"") | P18: =IF($B18=739,SUM($G18-(SUM($H18:$I18))),"") | Q18: =IF($B18=714,SUM($G18-(SUM($H18:$I18))),"") | R18: =IF($B18=710,SUM($G18-(SUM($H18:$I18))),"") | S18: =IF($B18=711,SUM($G18-(SUM($H18:$I18))),"") -> 0 | T18: =IF($B18=712,SUM($G18-(SUM($H18:$I18))),"") | U18: =IF($B18=713,SUM($G18-(SUM($H18:$I18))),"") | V18: =IF($B18=715,SUM($G18-(SUM($H18:$I18))),"") | W18: =IF($B18=724,SUM($G18-(SUM($H18:$I18))),"") | X18: =IF($B18=725,SUM($G18-(SUM($H18:$I18))),"") | Y18: =IF($B18=726,SUM($G18-(SUM($H18:$I18))),"") | Z18: =IF($B18=727,SUM($G18-(SUM($H18:$I18))),"") | AA18: =IF($B18=728,SUM($G18-(SUM($H18:$I18))),"") | AB18: =IF($B18=729,SUM($G18-(SUM($H18:$I18))),"") | AC18: =IF($B18=730,SUM($G18-(SUM($H18:$I18))),"") | AD18: =IF($B18=732,SUM($G18-(SUM($H18:$I18))),"") | AE18: =IF($B18=733,SUM($G18-(SUM($H18:$I18))),"") | AF18: =IF($B18=734,SUM($G18-(SUM($H18:$I18))),"") | AG18: =IF($B18=705,SUM($G18-(SUM($H18:$I18))),"") | AH18: =IF($B18=735,SUM($G18-(SUM($H18:$I18))),"") | AI18: =IF($B18=736,SUM($G18-(SUM($H18:$I18))),"") | AJ18: =IF($B18=737,SUM($G18-(SUM($H18:$I18))),"") | AK18: =IF($B18=725,SUM($G18-(SUM($H18:$I18))),"") | AL18: =IF($B18=735,SUM($G18-(SUM($H18:$I18))),"") | AM18: =IF($B18=727,SUM($G18-(SUM($H18:$I18))),"") | AN18: =IF($B18=718,SUM($G18-(SUM($H18:$I18))),"") | AO18: =IF($B18=719,SUM($G18-(SUM($H18:$I18))),"") | AP18: =IF($B18=717,SUM($G18-(SUM($H18:$I18))),"") | AQ18: =IF($B18=722,SUM($G18-(SUM($H18:$I18))),"") | AR18: =IF($B18=708,SUM($G18-(SUM($H18:$I18))),"") | AS18: =IF($B18=701,SUM($G18-(SUM($H18:$I18))),"") | AT18: =IF($B18=702,SUM($G18-(SUM($H18:$I18))),"") | AU18: =IF($B18=731,SUM($G18-(SUM($H18:$I18))),"") | AV18: =IF($B18=730,SUM($G18-(SUM($H18:$I18))),"")
B19: 733 | C19: Body Corp Fees / Council Rates | D19: =D18+G19 -> 0 | F19: =SUM(H19:AV19)-G19 -> 0 | G19: 0 | H19: =IF(G19/23*3>0,SUM(G19/23*3),"") | I19: =IF(G19/23*3<0,SUM(G19/23*3),"") | J19: =IF($B19=707,SUM($G19-(SUM($H19:$I19))),"") | K19: =IF($B19=706,SUM($G19-(SUM($H19:$I19))),"") | L19: =IF($B19=703,SUM($G19-(SUM($H19:$I19))),"") | M19: =IF($B19=704,SUM($G19-(SUM($H19:$I19))),"") | N19: =IF($B19=709,SUM($G19-(SUM($H19:$I19))),"") | O19: =IF($B19=738,SUM($G19-(SUM($H19:$I19))),"") | P19: =IF($B19=739,SUM($G19-(SUM($H19:$I19))),"") | Q19: =IF($B19=714,SUM($G19-(SUM($H19:$I19))),"") | R19: =IF($B19=710,SUM($G19-(SUM($H19:$I19))),"") | S19: =IF($B19=711,SUM($G19-(SUM($H19:$I19))),"") | T19: =IF($B19=712,SUM($G19-(SUM($H19:$I19))),"") | U19: =IF($B19=713,SUM($G19-(SUM($H19:$I19))),"") | V19: =IF($B19=715,SUM($G19-(SUM($H19:$I19))),"") | W19: =IF($B19=724,SUM($G19-(SUM($H19:$I19))),"") | X19: =IF($B19=725,SUM($G19-(SUM($H19:$I19))),"") | Y19: =IF($B19=726,SUM($G19-(SUM($H19:$I19))),"") | Z19: =IF($B19=727,SUM($G19-(SUM($H19:$I19))),"") | AA19: =IF($B19=728,SUM($G19-(SUM($H19:$I19))),"") | AB19: =IF($B19=729,SUM($G19-(SUM($H19:$I19))),"") | AC19: =IF($B19=730,SUM($G19-(SUM($H19:$I19))),"") | AD19: =IF($B19=732,SUM($G19-(SUM($H19:$I19))),"") | AE19: =IF($B19=733,SUM($G19-(SUM($H19:$I19))),"") -> 0 | AF19: =IF($B19=734,SUM($G19-(SUM($H19:$I19))),"") | AG19: =IF($B19=705,SUM($G19-(SUM($H19:$I19))),"") | AH19: =IF($B19=735,SUM($G19-(SUM($H19:$I19))),"") | AI19: =IF($B19=736,SUM($G19-(SUM($H19:$I19))),"") | AJ19: =IF($B19=737,SUM($G19-(SUM($H19:$I19))),"") | AK19: =IF($B19=725,SUM($G19-(SUM($H19:$I19))),"") | AL19: =IF($B19=735,SUM($G19-(SUM($H19:$I19))),"") | AM19: =IF($B19=727,SUM($G19-(SUM($H19:$I19))),"") | AN19: =IF($B19=718,SUM($G19-(SUM($H19:$I19))),"") | AO19: =IF($B19=719,SUM($G19-(SUM($H19:$I19))),"") | AP19: =IF($B19=717,SUM($G19-(SUM($H19:$I19))),"") | AQ19: =IF($B19=722,SUM($G19-(SUM($H19:$I19))),"") | AR19: =IF($B19=708,SUM($G19-(SUM($H19:$I19))),"") | AS19: =IF($B19=701,SUM($G19-(SUM($H19:$I19))),"") | AT19: =IF($B19=702,SUM($G19-(SUM($H19:$I19))),"") | AU19: =IF($B19=731,SUM($G19-(SUM($H19:$I19))),"") | AV19: =IF($B19=730,SUM($G19-(SUM($H19:$I19))),"")
B20: 739 | C20: Online Tech Subscriptions (NO GST) | D20: =D19+G20 -> 0 | F20: =SUM(H20:AV20)-G20 -> 0 | G20: 0 | H20: =IF(G20/23*3>0,SUM(G20/23*3),"") | I20: 0 | J20: =IF($B20=707,SUM($G20-(SUM($H20:$I20))),"") | K20: =IF($B20=706,SUM($G20-(SUM($H20:$I20))),"") | L20: =IF($B20=703,SUM($G20-(SUM($H20:$I20))),"") | M20: =IF($B20=704,SUM($G20-(SUM($H20:$I20))),"") | N20: =IF($B20=709,SUM($G20-(SUM($H20:$I20))),"") | O20: =IF($B20=738,SUM($G20-(SUM($H20:$I20))),"") | P20: =IF($B20=739,SUM($G20-(SUM($H20:$I20))),"") -> 0 | Q20: =IF($B20=714,SUM($G20-(SUM($H20:$I20))),"") | R20: =IF($B20=710,SUM($G20-(SUM($H20:$I20))),"") | S20: =IF($B20=711,SUM($G20-(SUM($H20:$I20))),"") | T20: =IF($B20=712,SUM($G20-(SUM($H20:$I20))),"") | U20: =IF($B20=713,SUM($G20-(SUM($H20:$I20))),"") | V20: =IF($B20=715,SUM($G20-(SUM($H20:$I20))),"") | W20: =IF($B20=724,SUM($G20-(SUM($H20:$I20))),"") | X20: =IF($B20=725,SUM($G20-(SUM($H20:$I20))),"") | Y20: =IF($B20=726,SUM($G20-(SUM($H20:$I20))),"") | Z20: =IF($B20=727,SUM($G20-(SUM($H20:$I20))),"") | AA20: =IF($B20=728,SUM($G20-(SUM($H20:$I20))),"") | AB20: =IF($B20=729,SUM($G20-(SUM($H20:$I20))),"") | AC20: =IF($B20=730,SUM($G20-(SUM($H20:$I20))),"") | AD20: =IF($B20=732,SUM($G20-(SUM($H20:$I20))),"") | AE20: =IF($B20=733,SUM($G20-(SUM($H20:$I20))),"") | AF20: =IF($B20=734,SUM($G20-(SUM($H20:$I20))),"") | AG20: =IF($B20=705,SUM($G20-(SUM($H20:$I20))),"") | AH20: =IF($B20=735,SUM($G20-(SUM($H20:$I20))),"") | AI20: =IF($B20=736,SUM($G20-(SUM($H20:$I20))),"") | AJ20: =IF($B20=737,SUM($G20-(SUM($H20:$I20))),"") | AK20: =IF($B20=725,SUM($G20-(SUM($H20:$I20))),"") | AL20: =IF($B20=735,SUM($G20-(SUM($H20:$I20))),"") | AM20: =IF($B20=727,SUM($G20-(SUM($H20:$I20))),"") | AN20: =IF($B20=718,SUM($G20-(SUM($H20:$I20))),"") | AO20: =IF($B20=719,SUM($G20-(SUM($H20:$I20))),"") | AP20: =IF($B20=717,SUM($G20-(SUM($H20:$I20))),"") | AQ20: =IF($B20=722,SUM($G20-(SUM($H20:$I20))),"") | AR20: =IF($B20=708,SUM($G20-(SUM($H20:$I20))),"") | AS20: =IF($B20=701,SUM($G20-(SUM($H20:$I20))),"") | AT20: =IF($B20=702,SUM($G20-(SUM($H20:$I20))),"") | AU20: =IF($B20=731,SUM($G20-(SUM($H20:$I20))),"") | AV20: =IF($B20=730,SUM($G20-(SUM($H20:$I20))),"")
B21: 739 | C21: Online Tech Subscriptions (NO GST) | D21: =D20+G21 -> 0 | F21: =SUM(H21:AV21)-G21 -> 0 | G21: 0 | H21: =IF(G21/23*3>0,SUM(G21/23*3),"") | I21: 0 | J21: =IF($B21=707,SUM($G21-(SUM($H21:$I21))),"") | K21: =IF($B21=706,SUM($G21-(SUM($H21:$I21))),"") | L21: =IF($B21=703,SUM($G21-(SUM($H21:$I21))),"") | M21: =IF($B21=704,SUM($G21-(SUM($H21:$I21))),"") | N21: =IF($B21=709,SUM($G21-(SUM($H21:$I21))),"") | O21: =IF($B21=738,SUM($G21-(SUM($H21:$I21))),"") | P21: =IF($B21=739,SUM($G21-(SUM($H21:$I21))),"") -> 0 | Q21: =IF($B21=714,SUM($G21-(SUM($H21:$I21))),"") | R21: =IF($B21=710,SUM($G21-(SUM($H21:$I21))),"") | S21: =IF($B21=711,SUM($G21-(SUM($H21:$I21))),"") | T21: =IF($B21=712,SUM($G21-(SUM($H21:$I21))),"") | U21: =IF($B21=713,SUM($G21-(SUM($H21:$I21))),"") | V21: =IF($B21=715,SUM($G21-(SUM($H21:$I21))),"") | W21: =IF($B21=724,SUM($G21-(SUM($H21:$I21))),"") | X21: =IF($B21=725,SUM($G21-(SUM($H21:$I21))),"") | Y21: =IF($B21=726,SUM($G21-(SUM($H21:$I21))),"") | Z21: =IF($B21=727,SUM($G21-(SUM($H21:$I21))),"") | AA21: =IF($B21=728,SUM($G21-(SUM($H21:$I21))),"") | AB21: =IF($B21=729,SUM($G21-(SUM($H21:$I21))),"") | AC21: =IF($B21=730,SUM($G21-(SUM($H21:$I21))),"") | AD21: =IF($B21=732,SUM($G21-(SUM($H21:$I21))),"") | AE21: =IF($B21=733,SUM($G21-(SUM($H21:$I21))),"") | AF21: =IF($B21=734,SUM($G21-(SUM($H21:$I21))),"") | AG21: =IF($B21=705,SUM($G21-(SUM($H21:$I21))),"") | AH21: =IF($B21=735,SUM($G21-(SUM($H21:$I21))),"") | AI21: =IF($B21=736,SUM($G21-(SUM($H21:$I21))),"") | AJ21: =IF($B21=737,SUM($G21-(SUM($H21:$I21))),"") | AK21: =IF($B21=725,SUM($G21-(SUM($H21:$I21))),"") | AL21: =IF($B21=735,SUM($G21-(SUM($H21:$I21))),"") | AM21: =IF($B21=727,SUM($G21-(SUM($H21:$I21))),"") | AN21: =IF($B21=718,SUM($G21-(SUM($H21:$I21))),"") | AO21: =IF($B21=719,SUM($G21-(SUM($H21:$I21))),"") | AP21: =IF($B21=717,SUM($G21-(SUM($H21:$I21))),"") | AQ21: =IF($B21=722,SUM($G21-(SUM($H21:$I21))),"") | AR21: =IF($B21=708,SUM($G21-(SUM($H21:$I21))),"") | AS21: =IF($B21=701,SUM($G21-(SUM($H21:$I21))),"") | AT21: =IF($B21=702,SUM($G21-(SUM($H21:$I21))),"") | AU21: =IF($B21=731,SUM($G21-(SUM($H21:$I21))),"") | AV21: =IF($B21=730,SUM($G21-(SUM($H21:$I21))),"")
B22: 730 | C22: Home Contents Insurance | D22: =D21+G22 -> 0 | F22: =SUM(H22:AV22)-G22 -> 0 | G22: 0 | H22: =IF(G22/23*3>0,SUM(G22/23*3),"") | I22: =IF(G22/23*3<0,SUM(G22/23*3),"") | J22: =IF($B22=707,SUM($G22-(SUM($H22:$I22))),"") | K22: =IF($B22=706,SUM($G22-(SUM($H22:$I22))),"") | L22: =IF($B22=703,SUM($G22-(SUM($H22:$I22))),"") | M22: =IF($B22=704,SUM($G22-(SUM($H22:$I22))),"") | N22: =IF($B22=709,SUM($G22-(SUM($H22:$I22))),"") | O22: =IF($B22=738,SUM($G22-(SUM($H22:$I22))),"") | P22: =IF($B22=739,SUM($G22-(SUM($H22:$I22))),"") | Q22: =IF($B22=714,SUM($G22-(SUM($H22:$I22))),"") | R22: =IF($B22=710,SUM($G22-(SUM($H22:$I22))),"") | S22: =IF($B22=711,SUM($G22-(SUM($H22:$I22))),"") | T22: =IF($B22=712,SUM($G22-(SUM($H22:$I22))),"") | U22: =IF($B22=713,SUM($G22-(SUM($H22:$I22))),"") | V22: =IF($B22=715,SUM($G22-(SUM($H22:$I22))),"") | W22: =IF($B22=724,SUM($G22-(SUM($H22:$I22))),"") | X22: =IF($B22=725,SUM($G22-(SUM($H22:$I22))),"") | Y22: =IF($B22=726,SUM($G22-(SUM($H22:$I22))),"") | Z22: =IF($B22=727,SUM($G22-(SUM($H22:$I22))),"") | AA22: =IF($B22=728,SUM($G22-(SUM($H22:$I22))),"") | AB22: =IF($B22=729,SUM($G22-(SUM($H22:$I22))),"") | AC22: =IF($B22=730,SUM($G22-(SUM($H22:$I22))),"") -> 0 | AD22: =IF($B22=732,SUM($G22-(SUM($H22:$I22))),"") | AE22: =IF($B22=733,SUM($G22-(SUM($H22:$I22))),"") | AF22: =IF($B22=734,SUM($G22-(SUM($H22:$I22))),"") | AG22: =IF($B22=705,SUM($G22-(SUM($H22:$I22))),"") | AH22: =IF($B22=735,SUM($G22-(SUM($H22:$I22))),"") | AI22: =IF($B22=736,SUM($G22-(SUM($H22:$I22))),"") | AJ22: =IF($B22=737,SUM($G22-(SUM($H22:$I22))),"") | AK22: =IF($B22=725,SUM($G22-(SUM($H22:$I22))),"") | AL22: =IF($B22=735,SUM($G22-(SUM($H22:$I22))),"") | AM22: =IF($B22=727,SUM($G22-(SUM($H22:$I22))),"") | AN22: =IF($B22=718,SUM($G22-(SUM($H22:$I22))),"") | AO22: =IF($B22=719,SUM($G22-(SUM($H22:$I22))),"") | AP22: =IF($B22=717,SUM($G22-(SUM($H22:$I22))),"") | AQ22: =IF($B22=722,SUM($G22-(SUM($H22:$I22))),"") | AR22: =IF($B22=708,SUM($G22-(SUM($H22:$I22))),"") | AS22: =IF($B22=701,SUM($G22-(SUM($H22:$I22))),"") | AT22: =IF($B22=702,SUM($G22-(SUM($H22:$I22))),"") | AU22: =IF($B22=731,SUM($G22-(SUM($H22:$I22))),"") | AV22: =IF($B22=730,SUM($G22-(SUM($H22:$I22))),"") -> 0
D23: =D22+G23 -> 0 | F23: =SUM(H23:AV23)-G23 -> 0 | H23: =IF(G23/23*3>0,SUM(G23/23*3),"") | I23: =IF(G23/23*3<0,SUM(G23/23*3),"") | J23: =IF($B23=707,SUM($G23-(SUM($H23:$I23))),"") | K23: =IF($B23=706,SUM($G23-(SUM($H23:$I23))),"") | L23: =IF($B23=703,SUM($G23-(SUM($H23:$I23))),"") | M23: =IF($B23=704,SUM($G23-(SUM($H23:$I23))),"") | N23: =IF($B23=709,SUM($G23-(SUM($H23:$I23))),"") | O23: =IF($B23=738,SUM($G23-(SUM($H23:$I23))),"") | P23: =IF($B23=739,SUM($G23-(SUM($H23:$I23))),"") | Q23: =IF($B23=714,SUM($G23-(SUM($H23:$I23))),"") | R23: =IF($B23=710,SUM($G23-(SUM($H23:$I23))),"") | S23: =IF($B23=711,SUM($G23-(SUM($H23:$I23))),"") | T23: =IF($B23=712,SUM($G23-(SUM($H23:$I23))),"") | U23: =IF($B23=713,SUM($G23-(SUM($H23:$I23))),"") | V23: =IF($B23=715,SUM($G23-(SUM($H23:$I23))),"") | W23: =IF($B23=724,SUM($G23-(SUM($H23:$I23))),"") | X23: =IF($B23=725,SUM($G23-(SUM($H23:$I23))),"") | Y23: =IF($B23=726,SUM($G23-(SUM($H23:$I23))),"") | Z23: =IF($B23=727,SUM($G23-(SUM($H23:$I23))),"") | AA23: =IF($B23=728,SUM($G23-(SUM($H23:$I23))),"") | AB23: =IF($B23=729,SUM($G23-(SUM($H23:$I23))),"") | AC23: =IF($B23=730,SUM($G23-(SUM($H23:$I23))),"") | AD23: =IF($B23=732,SUM($G23-(SUM($H23:$I23))),"") | AE23: =IF($B23=733,SUM($G23-(SUM($H23:$I23))),"") | AF23: =IF($B23=734,SUM($G23-(SUM($H23:$I23))),"") | AG23: =IF($B23=705,SUM($G23-(SUM($H23:$I23))),"") | AH23: =IF($B23=735,SUM($G23-(SUM($H23:$I23))),"") | AI23: =IF($B23=736,SUM($G23-(SUM($H23:$I23))),"") | AJ23: =IF($B23=737,SUM($G23-(SUM($H23:$I23))),"") | AK23: =IF($B23=725,SUM($G23-(SUM($H23:$I23))),"") | AL23: =IF($B23=735,SUM($G23-(SUM($H23:$I23))),"") | AM23: =IF($B23=727,SUM($G23-(SUM($H23:$I23))),"") | AN23: =IF($B23=718,SUM($G23-(SUM($H23:$I23))),"") | AO23: =IF($B23=719,SUM($G23-(SUM($H23:$I23))),"") | AP23: =IF($B23=717,SUM($G23-(SUM($H23:$I23))),"") | AQ23: =IF($B23=722,SUM($G23-(SUM($H23:$I23))),"") | AR23: =IF($B23=708,SUM($G23-(SUM($H23:$I23))),"") | AS23: =IF($B23=701,SUM($G23-(SUM($H23:$I23))),"") | AT23: =IF($B23=702,SUM($G23-(SUM($H23:$I23))),"") | AU23: =IF($B23=731,SUM($G23-(SUM($H23:$I23))),"") | AV23: =IF($B23=730,SUM($G23-(SUM($H23:$I23))),"")
B24: 707 | C24: Income - November - Client (50% progress payment received) | D24: =D23+G24 -> 0 | F24: =SUM(H24:AV24)-G24 -> 0 | G24: 0 | H24: =IF(G24/23*3>0,SUM(G24/23*3),"") | I24: =IF(G24/23*3<0,SUM(G24/23*3),"") | J24: =IF($B24=707,SUM($G24-(SUM($H24:$I24))),"") -> 0 | K24: =IF($B24=706,SUM($G24-(SUM($H24:$I24))),"") | L24: =IF($B24=703,SUM($G24-(SUM($H24:$I24))),"") | M24: =IF($B24=704,SUM($G24-(SUM($H24:$I24))),"") | N24: =IF($B24=709,SUM($G24-(SUM($H24:$I24))),"") | O24: =IF($B24=738,SUM($G24-(SUM($H24:$I24))),"") | P24: =IF($B24=739,SUM($G24-(SUM($H24:$I24))),"") | Q24: =IF($B24=714,SUM($G24-(SUM($H24:$I24))),"") | R24: =IF($B24=710,SUM($G24-(SUM($H24:$I24))),"") | S24: =IF($B24=711,SUM($G24-(SUM($H24:$I24))),"") | T24: =IF($B24=712,SUM($G24-(SUM($H24:$I24))),"") | U24: =IF($B24=713,SUM($G24-(SUM($H24:$I24))),"") | V24: =IF($B24=715,SUM($G24-(SUM($H24:$I24))),"") | W24: =IF($B24=724,SUM($G24-(SUM($H24:$I24))),"") | X24: =IF($B24=725,SUM($G24-(SUM($H24:$I24))),"") | Y24: =IF($B24=726,SUM($G24-(SUM($H24:$I24))),"") | Z24: =IF($B24=727,SUM($G24-(SUM($H24:$I24))),"") | AA24: =IF($B24=728,SUM($G24-(SUM($H24:$I24))),"") | AB24: =IF($B24=729,SUM($G24-(SUM($H24:$I24))),"") | AC24: =IF($B24=730,SUM($G24-(SUM($H24:$I24))),"") | AD24: =IF($B24=732,SUM($G24-(SUM($H24:$I24))),"") | AE24: =IF($B24=733,SUM($G24-(SUM($H24:$I24))),"") | AF24: =IF($B24=734,SUM($G24-(SUM($H24:$I24))),"") | AG24: =IF($B24=705,SUM($G24-(SUM($H24:$I24))),"") | AH24: =IF($B24=735,SUM($G24-(SUM($H24:$I24))),"") | AI24: =IF($B24=736,SUM($G24-(SUM($H24:$I24))),"") | AJ24: =IF($B24=737,SUM($G24-(SUM($H24:$I24))),"") | AK24: =IF($B24=725,SUM($G24-(SUM($H24:$I24))),"") | AL24: =IF($B24=735,SUM($G24-(SUM($H24:$I24))),"") | AM24: =IF($B24=727,SUM($G24-(SUM($H24:$I24))),"") | AN24: =IF($B24=718,SUM($G24-(SUM($H24:$I24))),"") | AO24: =IF($B24=719,SUM($G24-(SUM($H24:$I24))),"") | AP24: =IF($B24=717,SUM($G24-(SUM($H24:$I24))),"") | AQ24: =IF($B24=722,SUM($G24-(SUM($H24:$I24))),"") | AR24: =IF($B24=708,SUM($G24-(SUM($H24:$I24))),"") | AS24: =IF($B24=701,SUM($G24-(SUM($H24:$I24))),"") | AT24: =IF($B24=702,SUM($G24-(SUM($H24:$I24))),"") | AU24: =IF($B24=731,SUM($G24-(SUM($H24:$I24))),"") | AV24: =IF($B24=730,SUM($G24-(SUM($H24:$I24))),"")
B25: 725 | C25: Power - Fibrewave | D25: =D24+G25 -> 0 | F25: =SUM(H25:AV25)-G25 -> 0 | G25: 0 | H25: =IF(G25/23*3>0,SUM(G25/23*3),"") | I25: =IF(G25/23*3<0,SUM(G25/23*3),"") | J25: =IF($B25=707,SUM($G25-(SUM($H25:$I25))),"") | K25: =IF($B25=706,SUM($G25-(SUM($H25:$I25))),"") | L25: =IF($B25=703,SUM($G25-(SUM($H25:$I25))),"") | M25: =IF($B25=704,SUM($G25-(SUM($H25:$I25))),"") | N25: =IF($B25=709,SUM($G25-(SUM($H25:$I25))),"") | O25: =IF($B25=738,SUM($G25-(SUM($H25:$I25))),"") | P25: =IF($B25=739,SUM($G25-(SUM($H25:$I25))),"") | Q25: =IF($B25=714,SUM($G25-(SUM($H25:$I25))),"") | R25: =IF($B25=710,SUM($G25-(SUM($H25:$I25))),"") | S25: =IF($B25=711,SUM($G25-(SUM($H25:$I25))),"") | T25: =IF($B25=712,SUM($G25-(SUM($H25:$I25))),"") | U25: =IF($B25=713,SUM($G25-(SUM($H25:$I25))),"") | V25: =IF($B25=715,SUM($G25-(SUM($H25:$I25))),"") | W25: =IF($B25=724,SUM($G25-(SUM($H25:$I25))),"") | X25: =IF($B25=725,SUM($G25-(SUM($H25:$I25))),"") -> 0 | Y25: =IF($B25=726,SUM($G25-(SUM($H25:$I25))),"") | Z25: =IF($B25=727,SUM($G25-(SUM($H25:$I25))),"") | AA25: =IF($B25=728,SUM($G25-(SUM($H25:$I25))),"") | AB25: =IF($B25=729,SUM($G25-(SUM($H25:$I25))),"") | AC25: =IF($B25=730,SUM($G25-(SUM($H25:$I25))),"") | AD25: =IF($B25=732,SUM($G25-(SUM($H25:$I25))),"") | AE25: =IF($B25=733,SUM($G25-(SUM($H25:$I25))),"") | AF25: =IF($B25=734,SUM($G25-(SUM($H25:$I25))),"") | AG25: =IF($B25=705,SUM($G25-(SUM($H25:$I25))),"") | AH25: =IF($B25=735,SUM($G25-(SUM($H25:$I25))),"") | AI25: =IF($B25=736,SUM($G25-(SUM($H25:$I25))),"") | AJ25: =IF($B25=737,SUM($G25-(SUM($H25:$I25))),"") | AK25: =IF($B25=725,SUM($G25-(SUM($H25:$I25))),"") -> 0 | AL25: =IF($B25=735,SUM($G25-(SUM($H25:$I25))),"") | AM25: =IF($B25=727,SUM($G25-(SUM($H25:$I25))),"") | AN25: =IF($B25=718,SUM($G25-(SUM($H25:$I25))),"") | AO25: =IF($B25=719,SUM($G25-(SUM($H25:$I25))),"") | AP25: =IF($B25=717,SUM($G25-(SUM($H25:$I25))),"") | AQ25: =IF($B25=722,SUM($G25-(SUM($H25:$I25))),"") | AR25: =IF($B25=708,SUM($G25-(SUM($H25:$I25))),"") | AS25: =IF($B25=701,SUM($G25-(SUM($H25:$I25))),"") | AT25: =IF($B25=702,SUM($G25-(SUM($H25:$I25))),"") | AU25: =IF($B25=731,SUM($G25-(SUM($H25:$I25))),"") | AV25: =IF($B25=730,SUM($G25-(SUM($H25:$I25))),"")
B26: 726 | C26: Entertainment (Business Lunch/Coffee/Meals/Drinks) | D26: =D25+G26 -> 0 | F26: =SUM(H26:AV26)-G26 -> 0 | G26: =-(OtherCalculation!C6) -> 0 | H26: =IF(G26/23*3>0,SUM(G26/23*3),"") | I26: =IF(G26/23*3<0,SUM(G26/23*3),"") | J26: =IF($B26=707,SUM($G26-(SUM($H26:$I26))),"") | K26: =IF($B26=706,SUM($G26-(SUM($H26:$I26))),"") | L26: =IF($B26=703,SUM($G26-(SUM($H26:$I26))),"") | M26: =IF($B26=704,SUM($G26-(SUM($H26:$I26))),"") | N26: =IF($B26=709,SUM($G26-(SUM($H26:$I26))),"") | O26: =IF($B26=738,SUM($G26-(SUM($H26:$I26))),"") | P26: =IF($B26=739,SUM($G26-(SUM($H26:$I26))),"") | Q26: =IF($B26=714,SUM($G26-(SUM($H26:$I26))),"") | R26: =IF($B26=710,SUM($G26-(SUM($H26:$I26))),"") | S26: =IF($B26=711,SUM($G26-(SUM($H26:$I26))),"") | T26: =IF($B26=712,SUM($G26-(SUM($H26:$I26))),"") | U26: =IF($B26=713,SUM($G26-(SUM($H26:$I26))),"") | V26: =IF($B26=715,SUM($G26-(SUM($H26:$I26))),"") | W26: =IF($B26=724,SUM($G26-(SUM($H26:$I26))),"") | X26: =IF($B26=725,SUM($G26-(SUM($H26:$I26))),"") | Y26: =IF($B26=726,SUM($G26-(SUM($H26:$I26))),"") -> 0 | Z26: =IF($B26=727,SUM($G26-(SUM($H26:$I26))),"") | AA26: =IF($B26=728,SUM($G26-(SUM($H26:$I26))),"") | AB26: =IF($B26=729,SUM($G26-(SUM($H26:$I26))),"") | AC26: =IF($B26=730,SUM($G26-(SUM($H26:$I26))),"") | AD26: =IF($B26=732,SUM($G26-(SUM($H26:$I26))),"") | AE26: =IF($B26=733,SUM($G26-(SUM($H26:$I26))),"") | AF26: =IF($B26=734,SUM($G26-(SUM($H26:$I26))),"") | AG26: =IF($B26=705,SUM($G26-(SUM($H26:$I26))),"") | AH26: =IF($B26=735,SUM($G26-(SUM($H26:$I26))),"") | AI26: =IF($B26=736,SUM($G26-(SUM($H26:$I26))),"") | AJ26: =IF($B26=737,SUM($G26-(SUM($H26:$I26))),"") | AK26: =IF($B26=725,SUM($G26-(SUM($H26:$I26))),"") | AL26: =IF($B26=735,SUM($G26-(SUM($H26:$I26))),"") | AM26: =IF($B26=727,SUM($G26-(SUM($H26:$I26))),"") | AN26: =IF($B26=718,SUM($G26-(SUM($H26:$I26))),"") | AO26: =IF($B26=719,SUM($G26-(SUM($H26:$I26))),"") | AP26: =IF($B26=717,SUM($G26-(SUM($H26:$I26))),"") | AQ26: =IF($B26=722,SUM($G26-(SUM($H26:$I26))),"") | AR26: =IF($B26=708,SUM($G26-(SUM($H26:$I26))),"") | AS26: =IF($B26=701,SUM($G26-(SUM($H26:$I26))),"") | AT26: =IF($B26=702,SUM($G26-(SUM($H26:$I26))),"") | AU26: =IF($B26=731,SUM($G26-(SUM($H26:$I26))),"") | AV26: =IF($B26=730,SUM($G26-(SUM($H26:$I26))),"")
B27: 727 | C27: Internet - Fibrewave | D27: =D26+G27 -> 0 | F27: =SUM(H27:AV27)-G27 -> 0 | G27: 0 | H27: =IF(G27/23*3>0,SUM(G27/23*3),"") | I27: =IF(G27/23*3<0,SUM(G27/23*3),"") | J27: =IF($B27=707,SUM($G27-(SUM($H27:$I27))),"") | K27: =IF($B27=706,SUM($G27-(SUM($H27:$I27))),"") | L27: =IF($B27=703,SUM($G27-(SUM($H27:$I27))),"") | M27: =IF($B27=704,SUM($G27-(SUM($H27:$I27))),"") | N27: =IF($B27=709,SUM($G27-(SUM($H27:$I27))),"") | O27: =IF($B27=738,SUM($G27-(SUM($H27:$I27))),"") | P27: =IF($B27=739,SUM($G27-(SUM($H27:$I27))),"") | Q27: =IF($B27=714,SUM($G27-(SUM($H27:$I27))),"") | R27: =IF($B27=710,SUM($G27-(SUM($H27:$I27))),"") | S27: =IF($B27=711,SUM($G27-(SUM($H27:$I27))),"") | T27: =IF($B27=712,SUM($G27-(SUM($H27:$I27))),"") | U27: =IF($B27=713,SUM($G27-(SUM($H27:$I27))),"") | V27: =IF($B27=715,SUM($G27-(SUM($H27:$I27))),"") | W27: =IF($B27=724,SUM($G27-(SUM($H27:$I27))),"") | X27: =IF($B27=725,SUM($G27-(SUM($H27:$I27))),"") | Y27: =IF($B27=726,SUM($G27-(SUM($H27:$I27))),"") | Z27: =IF($B27=727,SUM($G27-(SUM($H27:$I27))),"") -> 0 | AA27: =IF($B27=728,SUM($G27-(SUM($H27:$I27))),"") | AB27: =IF($B27=729,SUM($G27-(SUM($H27:$I27))),"") | AC27: =IF($B27=730,SUM($G27-(SUM($H27:$I27))),"") | AD27: =IF($B27=732,SUM($G27-(SUM($H27:$I27))),"") | AE27: =IF($B27=733,SUM($G27-(SUM($H27:$I27))),"") | AF27: =IF($B27=734,SUM($G27-(SUM($H27:$I27))),"") | AG27: =IF($B27=705,SUM($G27-(SUM($H27:$I27))),"") | AH27: =IF($B27=735,SUM($G27-(SUM($H27:$I27))),"") | AI27: =IF($B27=736,SUM($G27-(SUM($H27:$I27))),"") | AJ27: =IF($B27=737,SUM($G27-(SUM($H27:$I27))),"") | AK27: =IF($B27=725,SUM($G27-(SUM($H27:$I27))),"") | AL27: =IF($B27=735,SUM($G27-(SUM($H27:$I27))),"") | AM27: =IF($B27=727,SUM($G27-(SUM($H27:$I27))),"") -> 0 | AN27: =IF($B27=718,SUM($G27-(SUM($H27:$I27))),"") | AO27: =IF($B27=719,SUM($G27-(SUM($H27:$I27))),"") | AP27: =IF($B27=717,SUM($G27-(SUM($H27:$I27))),"") | AQ27: =IF($B27=722,SUM($G27-(SUM($H27:$I27))),"") | AR27: =IF($B27=708,SUM($G27-(SUM($H27:$I27))),"") | AS27: =IF($B27=701,SUM($G27-(SUM($H27:$I27))),"") | AT27: =IF($B27=702,SUM($G27-(SUM($H27:$I27))),"") | AU27: =IF($B27=731,SUM($G27-(SUM($H27:$I27))),"") | AV27: =IF($B27=730,SUM($G27-(SUM($H27:$I27))),"")
B28: 728 | C28: Mobile Plan - Tui Mobile NZ | D28: =D27+G28 -> 0 | F28: =SUM(H28:AV28)-G28 -> 0 | G28: 0 | H28: =IF(G28/23*3>0,SUM(G28/23*3),"") | I28: =IF(G28/23*3<0,SUM(G28/23*3),"") | J28: =IF($B28=707,SUM($G28-(SUM($H28:$I28))),"") | K28: =IF($B28=706,SUM($G28-(SUM($H28:$I28))),"") | L28: =IF($B28=703,SUM($G28-(SUM($H28:$I28))),"") | M28: =IF($B28=704,SUM($G28-(SUM($H28:$I28))),"") | N28: =IF($B28=709,SUM($G28-(SUM($H28:$I28))),"") | O28: =IF($B28=738,SUM($G28-(SUM($H28:$I28))),"") | P28: =IF($B28=739,SUM($G28-(SUM($H28:$I28))),"") | Q28: =IF($B28=714,SUM($G28-(SUM($H28:$I28))),"") | R28: =IF($B28=710,SUM($G28-(SUM($H28:$I28))),"") | S28: =IF($B28=711,SUM($G28-(SUM($H28:$I28))),"") | T28: =IF($B28=712,SUM($G28-(SUM($H28:$I28))),"") | U28: =IF($B28=713,SUM($G28-(SUM($H28:$I28))),"") | V28: =IF($B28=715,SUM($G28-(SUM($H28:$I28))),"") | W28: =IF($B28=724,SUM($G28-(SUM($H28:$I28))),"") | X28: =IF($B28=725,SUM($G28-(SUM($H28:$I28))),"") | Y28: =IF($B28=726,SUM($G28-(SUM($H28:$I28))),"") | Z28: =IF($B28=727,SUM($G28-(SUM($H28:$I28))),"") | AA28: =IF($B28=728,SUM($G28-(SUM($H28:$I28))),"") -> 0 | AB28: =IF($B28=729,SUM($G28-(SUM($H28:$I28))),"") | AC28: =IF($B28=730,SUM($G28-(SUM($H28:$I28))),"") | AD28: =IF($B28=732,SUM($G28-(SUM($H28:$I28))),"") | AE28: =IF($B28=733,SUM($G28-(SUM($H28:$I28))),"") | AF28: =IF($B28=734,SUM($G28-(SUM($H28:$I28))),"") | AG28: =IF($B28=705,SUM($G28-(SUM($H28:$I28))),"") | AH28: =IF($B28=735,SUM($G28-(SUM($H28:$I28))),"") | AI28: =IF($B28=736,SUM($G28-(SUM($H28:$I28))),"") | AJ28: =IF($B28=737,SUM($G28-(SUM($H28:$I28))),"") | AK28: =IF($B28=725,SUM($G28-(SUM($H28:$I28))),"") | AL28: =IF($B28=735,SUM($G28-(SUM($H28:$I28))),"") | AM28: =IF($B28=727,SUM($G28-(SUM($H28:$I28))),"") | AN28: =IF($B28=718,SUM($G28-(SUM($H28:$I28))),"") | AO28: =IF($B28=719,SUM($G28-(SUM($H28:$I28))),"") | AP28: =IF($B28=717,SUM($G28-(SUM($H28:$I28))),"") | AQ28: =IF($B28=722,SUM($G28-(SUM($H28:$I28))),"") | AR28: =IF($B28=708,SUM($G28-(SUM($H28:$I28))),"") | AS28: =IF($B28=701,SUM($G28-(SUM($H28:$I28))),"") | AT28: =IF($B28=702,SUM($G28-(SUM($H28:$I28))),"") | AU28: =IF($B28=731,SUM($G28-(SUM($H28:$I28))),"") | AV28: =IF($B28=730,SUM($G28-(SUM($H28:$I28))),"")
B29: 729 | C29: Car Park Fees | D29: =D28+G29 -> 0 | F29: =SUM(H29:AV29)-G29 -> 0 | G29: 0 | H29: =IF(G29/23*3>0,SUM(G29/23*3),"") | I29: =IF(G29/23*3<0,SUM(G29/23*3),"") | J29: =IF($B29=707,SUM($G29-(SUM($H29:$I29))),"") | K29: =IF($B29=706,SUM($G29-(SUM($H29:$I29))),"") | L29: =IF($B29=703,SUM($G29-(SUM($H29:$I29))),"") | M29: =IF($B29=704,SUM($G29-(SUM($H29:$I29))),"") | N29: =IF($B29=709,SUM($G29-(SUM($H29:$I29))),"") | O29: =IF($B29=738,SUM($G29-(SUM($H29:$I29))),"") | P29: =IF($B29=739,SUM($G29-(SUM($H29:$I29))),"") | Q29: =IF($B29=714,SUM($G29-(SUM($H29:$I29))),"") | R29: =IF($B29=710,SUM($G29-(SUM($H29:$I29))),"") | S29: =IF($B29=711,SUM($G29-(SUM($H29:$I29))),"") | T29: =IF($B29=712,SUM($G29-(SUM($H29:$I29))),"") | U29: =IF($B29=713,SUM($G29-(SUM($H29:$I29))),"") | V29: =IF($B29=715,SUM($G29-(SUM($H29:$I29))),"") | W29: =IF($B29=724,SUM($G29-(SUM($H29:$I29))),"") | X29: =IF($B29=725,SUM($G29-(SUM($H29:$I29))),"") | Y29: =IF($B29=726,SUM($G29-(SUM($H29:$I29))),"") | Z29: =IF($B29=727,SUM($G29-(SUM($H29:$I29))),"") | AA29: =IF($B29=728,SUM($G29-(SUM($H29:$I29))),"") | AB29: =IF($B29=729,SUM($G29-(SUM($H29:$I29))),"") -> 0 | AC29: =IF($B29=730,SUM($G29-(SUM($H29:$I29))),"") | AD29: =IF($B29=732,SUM($G29-(SUM($H29:$I29))),"") | AE29: =IF($B29=733,SUM($G29-(SUM($H29:$I29))),"") | AF29: =IF($B29=734,SUM($G29-(SUM($H29:$I29))),"") | AG29: =IF($B29=705,SUM($G29-(SUM($H29:$I29))),"") | AH29: =IF($B29=735,SUM($G29-(SUM($H29:$I29))),"") | AI29: =IF($B29=736,SUM($G29-(SUM($H29:$I29))),"") | AJ29: =IF($B29=737,SUM($G29-(SUM($H29:$I29))),"") | AK29: =IF($B29=725,SUM($G29-(SUM($H29:$I29))),"") | AL29: =IF($B29=735,SUM($G29-(SUM($H29:$I29))),"") | AM29: =IF($B29=727,SUM($G29-(SUM($H29:$I29))),"") | AN29: =IF($B29=718,SUM($G29-(SUM($H29:$I29))),"") | AO29: =IF($B29=719,SUM($G29-(SUM($H29:$I29))),"") | AP29: =IF($B29=717,SUM($G29-(SUM($H29:$I29))),"") | AQ29: =IF($B29=722,SUM($G29-(SUM($H29:$I29))),"") | AR29: =IF($B29=708,SUM($G29-(SUM($H29:$I29))),"") | AS29: =IF($B29=701,SUM($G29-(SUM($H29:$I29))),"") | AT29: =IF($B29=702,SUM($G29-(SUM($H29:$I29))),"") | AU29: =IF($B29=731,SUM($G29-(SUM($H29:$I29))),"") | AV29: =IF($B29=730,SUM($G29-(SUM($H29:$I29))),"")
B30: 734 | C30: Home Office Expenses | D30: =D29+G30 -> 0 | F30: =SUM(H30:AV30)-G30 -> 0 | G30: 0 | H30: =IF(G30/23*3>0,SUM(G30/23*3),"") | I30: =IF(G30/23*3<0,SUM(G30/23*3),"") | J30: =IF($B30=707,SUM($G30-(SUM($H30:$I30))),"") | K30: =IF($B30=706,SUM($G30-(SUM($H30:$I30))),"") | L30: =IF($B30=703,SUM($G30-(SUM($H30:$I30))),"") | M30: =IF($B30=704,SUM($G30-(SUM($H30:$I30))),"") | N30: =IF($B30=709,SUM($G30-(SUM($H30:$I30))),"") | O30: =IF($B30=738,SUM($G30-(SUM($H30:$I30))),"") | P30: =IF($B30=739,SUM($G30-(SUM($H30:$I30))),"") | Q30: =IF($B30=714,SUM($G30-(SUM($H30:$I30))),"") | R30: =IF($B30=710,SUM($G30-(SUM($H30:$I30))),"") | S30: =IF($B30=711,SUM($G30-(SUM($H30:$I30))),"") | T30: =IF($B30=712,SUM($G30-(SUM($H30:$I30))),"") | U30: =IF($B30=713,SUM($G30-(SUM($H30:$I30))),"") | V30: =IF($B30=715,SUM($G30-(SUM($H30:$I30))),"") | W30: =IF($B30=724,SUM($G30-(SUM($H30:$I30))),"") | X30: =IF($B30=725,SUM($G30-(SUM($H30:$I30))),"") | Y30: =IF($B30=726,SUM($G30-(SUM($H30:$I30))),"") | Z30: =IF($B30=727,SUM($G30-(SUM($H30:$I30))),"") | AA30: =IF($B30=728,SUM($G30-(SUM($H30:$I30))),"") | AB30: =IF($B30=729,SUM($G30-(SUM($H30:$I30))),"") | AC30: =IF($B30=730,SUM($G30-(SUM($H30:$I30))),"") | AD30: =IF($B30=732,SUM($G30-(SUM($H30:$I30))),"") | AE30: =IF($B30=733,SUM($G30-(SUM($H30:$I30))),"") | AF30: =IF($B30=734,SUM($G30-(SUM($H30:$I30))),"") -> 0 | AG30: =IF($B30=705,SUM($G30-(SUM($H30:$I30))),"") | AH30: =IF($B30=735,SUM($G30-(SUM($H30:$I30))),"") | AI30: =IF($B30=736,SUM($G30-(SUM($H30:$I30))),"") | AJ30: =IF($B30=737,SUM($G30-(SUM($H30:$I30))),"") | AK30: =IF($B30=725,SUM($G30-(SUM($H30:$I30))),"") | AL30: =IF($B30=735,SUM($G30-(SUM($H30:$I30))),"") | AM30: =IF($B30=727,SUM($G30-(SUM($H30:$I30))),"") | AN30: =IF($B30=718,SUM($G30-(SUM($H30:$I30))),"") | AO30: =IF($B30=719,SUM($G30-(SUM($H30:$I30))),"") | AP30: =IF($B30=717,SUM($G30-(SUM($H30:$I30))),"") | AQ30: =IF($B30=722,SUM($G30-(SUM($H30:$I30))),"") | AR30: =IF($B30=708,SUM($G30-(SUM($H30:$I30))),"") | AS30: =IF($B30=701,SUM($G30-(SUM($H30:$I30))),"") | AT30: =IF($B30=702,SUM($G30-(SUM($H30:$I30))),"") | AU30: =IF($B30=731,SUM($G30-(SUM($H30:$I30))),"") | AV30: =IF($B30=730,SUM($G30-(SUM($H30:$I30))),"")
B31: 724 | C31: Apartment Rent | D31: =D30+G31 -> 0 | F31: =SUM(H31:AV31)-G31 -> 0 | G31: 0 | H31: =IF(G31/23*3>0,SUM(G31/23*3),"") | J31: =IF($B31=707,SUM($G31-(SUM($H31:$I31))),"") | K31: =IF($B31=706,SUM($G31-(SUM($H31:$I31))),"") | L31: =IF($B31=703,SUM($G31-(SUM($H31:$I31))),"") | M31: =IF($B31=704,SUM($G31-(SUM($H31:$I31))),"") | N31: =IF($B31=709,SUM($G31-(SUM($H31:$I31))),"") | O31: =IF($B31=738,SUM($G31-(SUM($H31:$I31))),"") | P31: =IF($B31=739,SUM($G31-(SUM($H31:$I31))),"") | Q31: =IF($B31=714,SUM($G31-(SUM($H31:$I31))),"") | R31: =IF($B31=710,SUM($G31-(SUM($H31:$I31))),"") | S31: =IF($B31=711,SUM($G31-(SUM($H31:$I31))),"") | T31: =IF($B31=712,SUM($G31-(SUM($H31:$I31))),"") | U31: =IF($B31=713,SUM($G31-(SUM($H31:$I31))),"") | V31: =IF($B31=715,SUM($G31-(SUM($H31:$I31))),"") | W31: =IF($B31=724,SUM($G31-(SUM($H31:$I31))),"") -> 0 | X31: =IF($B31=725,SUM($G31-(SUM($H31:$I31))),"") | Y31: =IF($B31=726,SUM($G31-(SUM($H31:$I31))),"") | Z31: =IF($B31=727,SUM($G31-(SUM($H31:$I31))),"") | AA31: =IF($B31=728,SUM($G31-(SUM($H31:$I31))),"") | AB31: =IF($B31=729,SUM($G31-(SUM($H31:$I31))),"") | AC31: =IF($B31=730,SUM($G31-(SUM($H31:$I31))),"") | AD31: =IF($B31=732,SUM($G31-(SUM($H31:$I31))),"") | AE31: =IF($B31=733,SUM($G31-(SUM($H31:$I31))),"") | AF31: =IF($B31=734,SUM($G31-(SUM($H31:$I31))),"") | AG31: =IF($B31=705,SUM($G31-(SUM($H31:$I31))),"") | AH31: =IF($B31=735,SUM($G31-(SUM($H31:$I31))),"") | AI31: =IF($B31=736,SUM($G31-(SUM($H31:$I31))),"") | AJ31: =IF($B31=737,SUM($G31-(SUM($H31:$I31))),"") | AK31: =IF($B31=725,SUM($G31-(SUM($H31:$I31))),"") | AL31: =IF($B31=735,SUM($G31-(SUM($H31:$I31))),"") | AM31: =IF($B31=727,SUM($G31-(SUM($H31:$I31))),"") | AN31: =IF($B31=718,SUM($G31-(SUM($H31:$I31))),"") | AO31: =IF($B31=719,SUM($G31-(SUM($H31:$I31))),"") | AP31: =IF($B31=717,SUM($G31-(SUM($H31:$I31))),"") | AQ31: =IF($B31=722,SUM($G31-(SUM($H31:$I31))),"") | AR31: =IF($B31=708,SUM($G31-(SUM($H31:$I31))),"") | AS31: =IF($B31=701,SUM($G31-(SUM($H31:$I31))),"") | AT31: =IF($B31=702,SUM($G31-(SUM($H31:$I31))),"") | AU31: =IF($B31=731,SUM($G31-(SUM($H31:$I31))),"") | AV31: =IF($B31=730,SUM($G31-(SUM($H31:$I31))),"")
